<?xml version="1.0" encoding="utf-8"?>
<!-- This URDF was automatically created by SolidWorks to URDF Exporter! Originally created by Stephen Brawner (brawner@gmail.com) 
     Commit Version: 1.6.0-1-g15f4949  Build Version: 1.6.7594.29634
     For more information, please see http://wiki.ros.org/sw_urdf_exporter -->
<robot
  name="j2_prototype3_3">
  <link
    name="base_link">
    <inertial>
      <origin
        xyz="0.113838723760159 0.122522758690537 -2.41527856573958E-16"
        rpy="0 0 0" />
      <mass
        value="2.04931359707062" />
      <inertia
        ixx="0.00533837054124555"
        ixy="0.000167708192149781"
        ixz="-1.23400118100656E-18"
        iyy="0.0176913297937821"
        iyz="-6.95596344943872E-18"
        izz="0.013602215383592" />
    </inertial>
    <visual>
      <origin
        xyz="0 0 0"
        rpy="0 0 0" />
      <geometry>
        <mesh
          filename="package://j2_prototype3_3/meshes/base_link.STL" />
      </geometry>
      <material
        name="">
        <color
          rgba="0.792156862745098 0.819607843137255 0.933333333333333 1" />
      </material>
    </visual>
    <collision>
      <origin
        xyz="0 0 0"
        rpy="0 0 0" />
      <geometry>
        <mesh
          filename="package://j2_prototype3_3/meshes/base_link.STL" />
      </geometry>
    </collision>
  </link>
  <link
    name="Link_0">
    <inertial>
      <origin
        xyz="0.11715 1.6183E-05 -0.01235"
        rpy="0 0 0" />
      <mass
        value="0.88481" />
      <inertia
        ixx="0.0014172"
        ixy="6.9386E-07"
        ixz="-3.6461E-06"
        iyy="0.0015808"
        iyz="1.6502E-07"
        izz="0.001695" />
    </inertial>
    <visual>
      <origin
        xyz="0 0 0"
        rpy="0 0 0" />
      <geometry>
        <mesh
          filename="package://j2_prototype3_3/meshes/Link_0.STL" />
      </geometry>
      <material
        name="">
        <color
          rgba="0.79216 0.81961 0.93333 1" />
      </material>
    </visual>
    <collision>
      <origin
        xyz="0 0 0"
        rpy="0 0 0" />
      <geometry>
        <mesh
          filename="package://j2_prototype3_3/meshes/Link_0.STL" />
      </geometry>
    </collision>
  </link>
  <joint
    name="Base_Rotate"
    type="revolute">
    <origin
      xyz="0.0483 0.1263 0"
      rpy="-1.5708 0 -1.5708" />
    <parent
      link="base_link" />
    <child
      link="Link_0" />
    <axis
      xyz="1 0 0" />
    <limit
      lower="-3.14"
      upper="3.14"
      effort="0"
      velocity="0" />
  </joint>
  <link
    name="Link_1">
    <inertial>
      <origin
        xyz="0.0857819637518 0.00580822512338842 0.150560483479643"
        rpy="0 0 0" />
      <mass
        value="1.65666298237923" />
      <inertia
        ixx="0.00776893592809935"
        ixy="-3.83296066990928E-06"
        ixz="-6.56645197721606E-06"
        iyy="0.00737009929368987"
        iyz="2.10121053232559E-06"
        izz="0.00233759453730666" />
    </inertial>
    <visual>
      <origin
        xyz="0 0 0"
        rpy="0 0 0" />
      <geometry>
        <mesh
          filename="package://j2_prototype3_3/meshes/Link_1.STL" />
      </geometry>
      <material
        name="">
        <color
          rgba="0.792156862745098 0.819607843137255 0.933333333333333 1" />
      </material>
    </visual>
    <collision>
      <origin
        xyz="0 0 0"
        rpy="0 0 0" />
      <geometry>
        <mesh
          filename="package://j2_prototype3_3/meshes/Link_1.STL" />
      </geometry>
    </collision>
  </link>
  <joint
    name="Limb_1"
    type="revolute">
    <origin
      xyz="0.126300000762939 0 -0.0383"
      rpy="0 -1.5707963267949 0" />
    <parent
      link="Link_0" />
    <child
      link="Link_1" />
    <axis
      xyz="-1 0 0" />
    <limit
      lower="-1.57"
      upper="1.57"
      effort="0"
      velocity="0" />
  </joint>
  <link
    name="Link_2">
    <inertial>
      <origin
        xyz="0.087782 0.0058082 0.15056"
        rpy="0 0 0" />
      <mass
        value="1.6567" />
      <inertia
        ixx="0.0077689"
        ixy="-3.833E-06"
        ixz="-6.5665E-06"
        iyy="0.0073701"
        iyz="2.1012E-06"
        izz="0.0023376" />
    </inertial>
    <visual>
      <origin
        xyz="0 0 0"
        rpy="0 0 0" />
      <geometry>
        <mesh
          filename="package://j2_prototype3_3/meshes/Link_2.STL" />
      </geometry>
      <material
        name="">
        <color
          rgba="0.79216 0.81961 0.93333 1" />
      </material>
    </visual>
    <collision>
      <origin
        xyz="0 0 0"
        rpy="0 0 0" />
      <geometry>
        <mesh
          filename="package://j2_prototype3_3/meshes/Link_2.STL" />
      </geometry>
    </collision>
  </link>
  <joint
    name="Limb_2"
    type="revolute">
    <origin
      xyz="0.0383 0.040299991703033 0.2"
      rpy="0 0 -1.5707963267949" />
    <parent
      link="Link_1" />
    <child
      link="Link_2" />
    <axis
      xyz="-1 0 0" />
    <limit
      lower="-1.57"
      upper="1.57"
      effort="0"
      velocity="0" />
  </joint>
  <link
    name="Link_3">
    <inertial>
      <origin
        xyz="0.0850855601631643 0.00453029722345037 0.149501795627794"
        rpy="0 0 0" />
      <mass
        value="1.65666298237921" />
      <inertia
        ixx="0.0077689359280993"
        ixy="-3.83296066990404E-06"
        ixz="-6.56645197735946E-06"
        iyy="0.00737009929368985"
        iyz="2.10121053224013E-06"
        izz="0.00233759453730661" />
    </inertial>
    <visual>
      <origin
        xyz="0 0 0"
        rpy="0 0 0" />
      <geometry>
        <mesh
          filename="package://j2_prototype3_3/meshes/Link_3.STL" />
      </geometry>
      <material
        name="">
        <color
          rgba="0.792156862745098 0.819607843137255 0.933333333333333 1" />
      </material>
    </visual>
    <collision>
      <origin
        xyz="0 0 0"
        rpy="0 0 0" />
      <geometry>
        <mesh
          filename="package://j2_prototype3_3/meshes/Link_3.STL" />
      </geometry>
    </collision>
  </link>
  <joint
    name="Limb_3"
    type="revolute">
    <origin
      xyz="0.041578 0.037604 0.20106"
      rpy="0 0 -1.5708" />
    <parent
      link="Link_2" />
    <child
      link="Link_3" />
    <axis
      xyz="-1 0 0" />
    <limit
      lower="-1.57"
      upper="1.57"
      effort="0"
      velocity="0" />
  </joint>
  <link
    name="Link_4">
    <inertial>
      <origin
        xyz="0.0877819622259346 0.00580822512339148 0.150560483479637"
        rpy="0 0 0" />
      <mass
        value="1.65666298237923" />
      <inertia
        ixx="0.00776893592809935"
        ixy="-3.83296066989214E-06"
        ixz="-6.56645197733124E-06"
        iyy="0.00737009929368986"
        iyz="2.10121053221037E-06"
        izz="0.00233759453730665" />
    </inertial>
    <visual>
      <origin
        xyz="0 0 0"
        rpy="0 0 0" />
      <geometry>
        <mesh
          filename="package://j2_prototype3_3/meshes/Link_4.STL" />
      </geometry>
      <material
        name="">
        <color
          rgba="0.792156862745098 0.819607843137255 0.933333333333333 1" />
      </material>
    </visual>
    <collision>
      <origin
        xyz="0 0 0"
        rpy="0 0 0" />
      <geometry>
        <mesh
          filename="package://j2_prototype3_3/meshes/Link_4.STL" />
      </geometry>
    </collision>
  </link>
  <joint
    name="Limb_4"
    type="revolute">
    <origin
      xyz="0.037604 0.039022 0.19894"
      rpy="0 0 -1.5708" />
    <parent
      link="Link_3" />
    <child
      link="Link_4" />
    <axis
      xyz="-1 0 0" />
    <limit
      lower="-1.57"
      upper="1.57"
      effort="0"
      velocity="0" />
  </joint>
  <link
    name="Link_5">
    <inertial>
      <origin
        xyz="0.092387346244534 2.43123029655484E-12 -3.51507711826571E-12"
        rpy="0 0 0" />
      <mass
        value="0.065637413377382" />
      <inertia
        ixx="7.05811091251407E-05"
        ixy="-2.8790112691653E-18"
        ixz="1.2728075300888E-17"
        iyy="3.63181467498312E-05"
        iyz="-8.5630899803323E-13"
        izz="3.63181467549861E-05" />
    </inertial>
    <visual>
      <origin
        xyz="0 0 0"
        rpy="0 0 0" />
      <geometry>
        <mesh
          filename="package://j2_prototype3_3/meshes/Link_5.STL" />
      </geometry>
      <material
        name="">
        <color
          rgba="0.792156862745098 0.819607843137255 0.933333333333333 1" />
      </material>
    </visual>
    <collision>
      <origin
        xyz="0 0 0"
        rpy="0 0 0" />
      <geometry>
        <mesh
          filename="package://j2_prototype3_3/meshes/Link_5.STL" />
      </geometry>
    </collision>
  </link>
  <joint
    name="Effector_Limb"
    type="revolute">
    <origin
      xyz="0.0403 0.0383 0.2"
      rpy="0 0 -1.5708" />
    <parent
      link="Link_4" />
    <child
      link="Link_5" />
    <axis
      xyz="-1 0 0" />
    <limit
      lower="-3.14"
      upper="3.14"
      effort="0"
      velocity="0" />
  </joint>
</robot>