<?xml version="1.0" encoding="utf-8" ?>
<!-- This URDF was automatically created by SolidWorks to URDF Exporter! Originally created by Stephen Brawner (brawner@gmail.com) 
     Commit Version: 1.6.0-1-g15f4949  Build Version: 1.6.7594.29634
     For more information, please see http://wiki.ros.org/sw_urdf_exporter -->
<robot name="adele_urdf_1">
    <link name="dummy" />
    <link name="base_link">
        
<inertial>
            <origin xyz="-0.00038775 -0.0004149 0.012549" rpy="0 0 0" />
            <mass value="1.7961" />
            <inertia ixx="0.0096875" ixy="-0.00010468" ixz="3.448E-06" iyy="0.013889" iyz="3.6895E-06" izz="0.02339" />
        </inertial>

        <visual>
            <origin xyz="0 0 0" rpy="0 0 0" />
            <geometry>
                <mesh filename="package://adele_urdf_1/meshes/base_link.STL" />
            </geometry>
            <material name="">
                <color rgba="0 0 0 1" />
            </material>
        </visual>
        <collision>
            <origin xyz="0 0 0" rpy="0 0 0" />
            <geometry>
                <mesh filename="package://adele_urdf_1/meshes/base_link.STL" />
            </geometry>
        </collision>
    </link>
    <joint name="dummy_joint" type="fixed">
        <parent link="dummy" />
        <child link="base_link" />
    </joint>
    <link name="link_1">
        
<inertial>
            <origin xyz="0.021715 -1.1671E-09 0.018917" rpy="0 0 0" />
            <mass value="0.5576" />
            <inertia ixx="0.00077362" ixy="-7.564E-12" ixz="-1.6834E-05" iyy="0.00079177" iyz="3.082E-12" izz="0.0014984" />
        </inertial>

        <visual>
            <origin xyz="0 0 0" rpy="0 0 0" />
            <geometry>
                <mesh filename="package://adele_urdf_1/meshes/link_1.STL" />
            </geometry>
            <material name="">
                <color rgba="0.90588 0.63529 0 1" />
            </material>
        </visual>
        <collision>
            <origin xyz="0 0 0" rpy="0 0 0" />
            <geometry>
                <mesh filename="package://adele_urdf_1/meshes/link_1.STL" />
            </geometry>
        </collision>
    </link>
    <joint name="base_joint" type="fixed">
        <origin xyz="-0.0299609304893849 -0.0421709713738316 0.0249999987602389" rpy="0 0 0" />
        <parent link="base_link" />
        <child link="link_1" />
        <axis xyz="0 0 0" />
    </joint>
    <link name="link_2">
        
<inertial>
            <origin xyz="-0.00946608000119067 -1.2068163925627E-05 0.0982578667649479" rpy="0 0 0" />
            <mass value="1.20054097225308" />
            <inertia ixx="0.00201947233992171" ixy="-1.64686049256727E-07" ixz="-3.64592823133029E-06" iyy="0.00190936196157968" iyz="-6.98758318609587E-07" izz="0.00199289212426803" />
        </inertial>

        <visual>
            <origin xyz="0 0 0" rpy="0 0 0" />
            <geometry>
                <mesh filename="package://adele_urdf_1/meshes/link_2.STL" />
            </geometry>
            <material name="">
                <color rgba="0.905882352941176 0.635294117647059 0 1" />
            </material>
        </visual>
        <collision>
            <origin xyz="0 0 0" rpy="0 0 0" />
            <geometry>
                <mesh filename="package://adele_urdf_1/meshes/link_2.STL" />
            </geometry>
        </collision>
    </link>
    <joint name="joint_1" type="continuous">
        <origin xyz="0 0 0" rpy="0 0 0" />
        <parent link="link_1" />
        <child link="link_2" />
        <axis xyz="0 0 -1" />
    </joint>
    <link name="link_3">
        
<inertial>
            <origin xyz="0.0949472296187238 0.00600525066072677 0.153030042562841" rpy="0 0 0" />
            <mass value="1.62557266260008" />
            <inertia ixx="0.0074572472446285" ixy="-3.64634636379706E-06" ixz="-1.30605666518055E-05" iyy="0.00708731534001816" iyz="-4.97298626019905E-07" izz="0.00230220778574052" />
        </inertial>

        <visual>
            <origin xyz="0 0 0" rpy="0 0 0" />
            <geometry>
                <mesh filename="package://adele_urdf_1/meshes/link_3.STL" />
            </geometry>
            <material name="">
                <color rgba="0.96078431372549 0.96078431372549 0.964705882352941 1" />
            </material>
        </visual>
        <collision>
            <origin xyz="0 0 0" rpy="0 0 0" />
            <geometry>
                <mesh filename="package://adele_urdf_1/meshes/link_3.STL" />
            </geometry>
        </collision>
    </link>
    <joint name="joint_2" type="revolute">
        <origin xyz="-0.0483 0 0.1263" rpy="0 0 0" />
        <parent link="link_2" />
        <child link="link_3" />
        <axis xyz="-1 0 0" />
        <limit lower="-1.57" upper="1.57" effort="0" velocity="0" />
    </joint>
    <link name="link_4">
        
<inertial>
            <origin xyz="0.0842508269161635 0.00472732276078493 0.151971355966426" rpy="0 0 0" />
            <mass value="1.62557266260007" />
            <inertia ixx="0.00745724724501772" ixy="-3.64634635640103E-06" ixz="-1.30604898358527E-05" iyy="0.00708731534001816" iyz="-4.97298680323451E-07" izz="0.00230220778535128" />
        </inertial>

        <visual>
            <origin xyz="0 0 0" rpy="0 0 0" />
            <geometry>
                <mesh filename="package://adele_urdf_1/meshes/link_4.STL" />
            </geometry>
            <material name="">
                <color rgba="0.96078431372549 0.96078431372549 0.964705882352941 1" />
            </material>
        </visual>
        <collision>
            <origin xyz="0 0 0" rpy="0 0 0" />
            <geometry>
                <mesh filename="package://adele_urdf_1/meshes/link_4.STL" />
            </geometry>
        </collision>
    </link>
    <joint name="joint_3" type="revolute">
        <origin xyz="0.049578 0.037604 0.20106" rpy="0 0 -1.5708" />
        <parent link="link_3" />
        <child link="link_4" />
        <axis xyz="-1 0 0" />
        <limit lower="-1.57" upper="1.57" effort="0" velocity="0" />
    </joint>
    <link name="link_5">
        
<inertial>
            <origin xyz="0.0949472296187236 0.00600525066072749 0.153030042562838" rpy="0 0 0" />
            <mass value="1.62557266260008" />
            <inertia ixx="0.0074572472446285" ixy="-3.64634636379064E-06" ixz="-1.3060566651786E-05" iyy="0.00708731534001815" iyz="-4.97298625970647E-07" izz="0.00230220778574053" />
        </inertial>

        <visual>
            <origin xyz="0 0 0" rpy="0 0 0" />
            <geometry>
                <mesh filename="package://adele_urdf_1/meshes/link_5.STL" />
            </geometry>
            <material name="">
                <color rgba="0.905882352941176 0.635294117647059 0 1" />
            </material>
        </visual>
        <collision>
            <origin xyz="0 0 0" rpy="0 0 0" />
            <geometry>
                <mesh filename="package://adele_urdf_1/meshes/link_5.STL" />
            </geometry>
        </collision>
    </link>
    <joint name="joint_4" type="revolute">
        <origin xyz="0.037604 0.047022 0.19894" rpy="0 0 -1.5708" />
        <parent link="link_4" />
        <child link="link_5" />
        <axis xyz="-1 0 0" />
        <limit lower="-1.57" upper="1.57" effort="0" velocity="0" />
    </joint>
    <link name="link_6">
        
<inertial>
            <origin xyz="0.11303274698715 0.00439754326362684 0.153440831764849" rpy="0 0 0" />
            <mass value="1.59785849274926" />
            <inertia ixx="0.00735773754641421" ixy="3.05006515332995E-06" ixz="2.83590075433729E-05" iyy="0.00701263930015728" iyz="-1.94387655967687E-06" izz="0.00224131785720291" />
        </inertial>

        <visual>
            <origin xyz="0 0 0" rpy="0 0 0" />
            <geometry>
                <mesh filename="package://adele_urdf_1/meshes/link_6.STL" />
            </geometry>
            <material name="">
                <color rgba="0.905882352941176 0.635294117647059 0 1" />
            </material>
        </visual>
        <collision>
            <origin xyz="0 0 0" rpy="0 0 0" />
            <geometry>
                <mesh filename="package://adele_urdf_1/meshes/link_6.STL" />
            </geometry>
        </collision>
    </link>
    <joint name="joint_5" type="revolute">
        <origin xyz="0.0483 0.065212 0.2" rpy="0 0 -1.5708" />
        <parent link="link_5" />
        <child link="link_6" />
        <axis xyz="-1 0 0" />
        <limit lower="-1.57" upper="1.57" effort="0" velocity="0" />
    </joint>
    <link name="link_7">
        
<inertial>
            <origin xyz="0.156332054157634 -1.37676720579627E-08 9.5567196056745E-07" rpy="0 0 0" />
            <mass value="0.245667965158845" />
            <inertia ixx="0.000292839789614645" ixy="5.45042400305886E-11" ixz="-1.2036401502341E-08" iyy="0.000224295830715086" iyz="6.66507572450264E-11" izz="0.000223856151587736" />
        </inertial>

        <visual>
            <origin xyz="0 0 0" rpy="0 0 0" />
            <geometry>
                <mesh filename="package://adele_urdf_1/meshes/link_7.STL" />
            </geometry>
            <material name="">
                <color rgba="0.905882352941176 0.635294117647059 0 1" />
            </material>
        </visual>
        <collision>
            <origin xyz="0 0 0" rpy="0 0 0" />
            <geometry>
                <mesh filename="package://adele_urdf_1/meshes/link_7.STL" />
            </geometry>
        </collision>
    </link>
    <joint name="joint_6" type="continuous">
        <origin xyz="0.065212 0.065212 0.2" rpy="0 0 -1.5708" />
        <parent link="link_6" />
        <child link="link_7" />
        <axis xyz="-1 0 0" />
        <limit lower="0" upper="0" effort="0" velocity="0" />
    </joint>
    
<transmission name="trans_joint_1">
        <type>transmission_interface/SimpleTransmission</type>
        <joint name="joint_1">
            <hardwareInterface>hardware_interface/PositionJointInterface</hardwareInterface>
        </joint>
        <actuator name="joint_1_motor">
            <hardwareInterface>hardware_interface/PositionJointInterface</hardwareInterface>
            <mechanicalReduction>1</mechanicalReduction>
        </actuator>
    </transmission>
    <transmission name="trans_joint_2">
        <type>transmission_interface/SimpleTransmission</type>
        <joint name="joint_2">
            <hardwareInterface>hardware_interface/PositionJointInterface</hardwareInterface>
        </joint>
        <actuator name="joint_2_motor">
            <hardwareInterface>hardware_interface/PositionJointInterface</hardwareInterface>
            <mechanicalReduction>20</mechanicalReduction>
        </actuator>
    </transmission>
    <transmission name="trans_joint_3">
        <type>transmission_interface/SimpleTransmission</type>
        <joint name="joint_3">
            <hardwareInterface>hardware_interface/PositionJointInterface</hardwareInterface>
        </joint>
        <actuator name="joint_3_motor">
            <hardwareInterface>hardware_interface/PositionJointInterface</hardwareInterface>
            <mechanicalReduction>20</mechanicalReduction>
        </actuator>
    </transmission>
    <transmission name="trans_joint_4">
        <type>transmission_interface/SimpleTransmission</type>
        <joint name="joint_4">
            <hardwareInterface>hardware_interface/PositionJointInterface</hardwareInterface>
        </joint>
        <actuator name="joint_4_motor">
            <hardwareInterface>hardware_interface/PositionJointInterface</hardwareInterface>
            <mechanicalReduction>20</mechanicalReduction>
        </actuator>
    </transmission>
    <transmission name="trans_joint_5">
        <type>transmission_interface/SimpleTransmission</type>
        <joint name="joint_5">
            <hardwareInterface>hardware_interface/PositionJointInterface</hardwareInterface>
        </joint>
        <actuator name="joint_5_motor">
            <hardwareInterface>hardware_interface/PositionJointInterface</hardwareInterface>
            <mechanicalReduction>20</mechanicalReduction>
        </actuator>
    </transmission>
    <transmission name="trans_joint_6">
        <type>transmission_interface/SimpleTransmission</type>
        <joint name="joint_6">
            <hardwareInterface>hardware_interface/PositionJointInterface</hardwareInterface>
        </joint>
        <actuator name="joint_6_motor">
            <hardwareInterface>hardware_interface/PositionJointInterface</hardwareInterface>
            <mechanicalReduction>6.5</mechanicalReduction>
        </actuator>
    </transmission>
    <gazebo>
        <plugin name="gazebo_ros_control" filename="libgazebo_ros_control.so">
            <robotNamespace>/</robotNamespace>
        </plugin>
    </gazebo>
</robot>
